<?xml version="1.0"?>
<robot xmlns:xacro="http://www.ros.org/wiki/xacro" name="VU-8">
  <xacro:property name="M_PI" value="3.1415926535897931" />

  <!-- Minimum horizontal angle is -100 DEG - Wide FOV -->
  <xacro:property name="min_horizontal_angle" value="-3.14159" />
  
  <!-- Maximum horizontal angle is 100 DEG - Wide FOV -->
  <xacro:property name="max_horizontal_angle" value="3.14159" />

  <!-- Minimum vertical angle is -3 DEG -->
  <xacro:property name="min_vertical_angle" value="-0.523599" />
  
  <!-- Maximum vertical angle is 3 DEG-->
  <xacro:property name="max_vertical_angle" value="0.523599" />

  <xacro:macro name="VU-8" params="
    *origin parent:=base_link name:=leddar topic:=/leddar_points hz:=10 lasers:=8 samples:=1875 collision_range:=0.3 min_range:=0.1 max_range:=130.0 noise:=0.008 gpu:=false">

    <joint name="${name}_base_mount_joint" type="fixed">
      <xacro:insert_block name="origin" /> 
      <parent link="${parent}"/>
      <child link="${name}_base_link"/>
    </joint>

    <link name="${name}_base_link">
      <inertial>
        <mass value="1e-2"/>
        <origin xyz="0 0 0.03585"/>
        <inertia ixx="1e-2" ixy="0" ixz="0" iyy="1e-2" iyz="0" izz="1e-2"/>
      </inertial>
      <visual>
        <geometry>
          <mesh filename="package://velodyne_description/meshes/VLP16_base_1.dae" />
        </geometry>
      </visual>
      <visual>
        <geometry>
          <mesh filename="package://velodyne_description/meshes/VLP16_base_2.dae" />
        </geometry>
      </visual>
      <collision>
        <origin rpy="0 0 0" xyz="0 0 0.03585"/>
        <geometry>
          <cylinder radius="0.0516" length="0.0717"/>
        </geometry>
      </collision>
    </link>

    <link name="rotating_${name}">
      <inertial>
        <mass value="1e-2"/>
        <origin xyz="0 0 0"/>
        <inertia ixx="1e-2" ixy="0" ixz="0" iyy="1e-2" iyz="0" izz="1e-2"/>
      </inertial>
      <visual>
        <origin xyz="0 0 -0.0377" />
        <geometry>
          <mesh filename="package://velodyne_description/meshes/VLP16_scan.dae" />
        </geometry>
      </visual>
    </link>

    <joint name="${name}_base_scan_joint" type="revolute" >
      <origin xyz="0 0 0.0377" rpy="0 0 0" />
      <parent link="${name}_base_link" />
      <child link="rotating_${name}"/>
      <limit effort="10.0" lower="-0.5" upper="0.5" velocity="0.1"/>
      <axis xyz="0 0 1" />
    </joint>

    <transmission name="simple_trans">
      <type>transmission_interface/SimpleTransmission</type>
      <joint name="${name}_base_scan_joint">
        <hardwareInterface>hardware_interface/EffortJointInterface</hardwareInterface>
      </joint>
      <actuator name="foo_motor">
        <hardwareInterface>hardware_interface/EffortJointInterface</hardwareInterface>
      </actuator>
    </transmission>

    <!-- Gazebo requires the velodyne_gazebo_plugins package -->
    <gazebo reference="rotating_${name}">
      <xacro:if value="${gpu}">
        <sensor type="gpu_ray" name="${name}-VU8">
          <pose>0 0 0 0 0 0</pose>
          <visualize>false</visualize>
          <update_rate>${hz}</update_rate>
          <ray>
            <scan>
              <horizontal>
                <samples>${samples}</samples>
                <resolution>1</resolution>
                <min_angle>${min_horizontal_angle}</min_angle>
                <max_angle>${max_horizontal_angle}</max_angle>
              </horizontal>
              <vertical>
                <samples>${lasers}</samples>
                <resolution>1</resolution>
                <min_angle>${min_vertical_angle}</min_angle>
                <max_angle>${max_vertical_angle}</max_angle>
              </vertical>
            </scan>
            <range>
              <min>${collision_range}</min>
              <max>${max_range+1}</max>
              <resolution>0.001</resolution>
            </range>
            <noise>
              <type>gaussian</type>
              <mean>0.0</mean>
              <stddev>0.0</stddev>
            </noise>
          </ray>
          <plugin name="gazebo_ros_laser_controller" filename="libgazebo_ros_velodyne_gpu_laser.so">
            <topicName>${topic}</topicName>
            <frameName>rotating_${name}</frameName>
            <min_range>${min_range}</min_range>
            <max_range>${max_range}</max_range>
            <gaussianNoise>${noise}</gaussianNoise>
            <staticFrameName>${name}_base_link</staticFrameName>
            <staticTopicName>${topic}_static</staticTopicName>
          </plugin>
        </sensor>
      </xacro:if>
      <xacro:unless value="${gpu}">
        <sensor type="ray" name="${name}-VU8">
          <pose>0 0 0 0 0 0</pose>
          <visualize>false</visualize>
          <update_rate>${hz}</update_rate>
          <ray>
            <scan>
              <horizontal>
                <samples>${samples}</samples>
                <resolution>1</resolution>
                <min_angle>${min_horizontal_angle}</min_angle>
                <max_angle>${max_horizontal_angle}</max_angle>
              </horizontal>
              <vertical>
                <samples>${lasers}</samples>
                <resolution>1</resolution>
                <min_angle>${min_vertical_angle}</min_angle>
                <max_angle>${max_vertical_angle}</max_angle>
              </vertical>
            </scan>
            <range>
              <min>${collision_range}</min>
              <max>${max_range+1}</max>
              <resolution>0.001</resolution>
            </range>
            <noise>
              <type>gaussian</type>
              <mean>0.0</mean>
              <stddev>0.0</stddev>
            </noise>
          </ray>
          <plugin name="gazebo_ros_laser_controller" filename="libgazebo_ros_velodyne_laser.so">
            <topicName>${topic}</topicName>
            <frameName>rotating_${name}</frameName>
            <min_range>${min_range}</min_range>
            <max_range>${max_range}</max_range>
            <gaussianNoise>${noise}</gaussianNoise>
            <staticFrameName>${name}_base_link</staticFrameName>
            <staticTopicName>${topic}_static</staticTopicName>
          </plugin>
        </sensor>
      </xacro:unless>
    </gazebo>

  </xacro:macro>
</robot>
